Workbook

Sheet Start here
B1: Kinetix programmes
B3: You write the programmes; the app scales them to each person. Write paces as zones (E, M, T, I, R) and running volume as a percentage of the runner's starting weekly volume. The app turns those into real paces (from their race time) and kilometres (from their 'current weekly volume' onboarding answer), places the sessions on their chosen days, and keeps balancing running and lifting as they train.
B4: When you've finished (or changed) something, send the file back and Claude converts it into the app's programme files, checks it, and shows sample plans for a few typical runners before anything goes to TestFlight.
B6: Colours
C7: Yellow cells: fill these in (drop-downs where there's a fixed list).
C8: Grey cells: worked out for you (checks and examples). Don't type here.
C9: Dark headers: column names. Hover a header for a note.
B11: Tabs, in the order to fill them
B12: Programmes | C12: One row per onboarding goal: length, runs and lifts per week, long-run cap, what happens at the end.
B13: Run weeks | C13: Every week of every programme: phase, volume (% of starting volume), long run, strength emphasis.
B14: Run sessions | C14: Every run in every week: type, key or optional, distance (or 'auto') and the workout.
B15: Pace zones | C15: What E / M / T / I / R mean. Change the descriptions or add an effort guide; paces come from race times.
B16: Strength splits | C16: The splits offered in onboarding (full body, upper/lower, PPL…): days per week and who they suit.
B17: Split days | C17: Each day of each split: exercises (a specific one or 'any squat' etc.), role, and optional sets/reps.
B18: Strength by goal | C18: Sets, reps and rest for main and accessory lifts, per goal (used unless a split day overrides them).
B19: Rules | C19: Safety limits and defaults: max weekly increase, starting volumes, long-run share, deload size.
B20: Lists | C20: The options behind the drop-downs. Add exercises here only if they're also added to the app.
B22: Writing a workout
B23: Zones | C23: @ E, STEADY, M, HM, T, 10K, 5K, I, R (see Pace zones). Add 'effort' (e.g. @ T effort) to show the pace as a guide only, with no off-pace warnings.
B24: Reps | C24: 6 x 800 m @ I, 90 s jog between 5 x 1 km @ I, 2 min jog between 2 x 8 min @ T, 2 min jog between
B25: Mixed reps | C25: 8 x (1 min @ I / 1 min E) 4 x (3 min @ 10K / 2 min @ HM / 1 min @ 5K / 2 min E)
B26: Continuous | C26: 15 min continuous @ T 25 min continuous @ T
B27: Hills | C27: 8 x 60 s uphill @ hard effort, jog back down (timed reps, no pace target)
B28: Progressions | C28: 4 km E → 3 km STEADY → 1 km HM (the km set the shape; the app sizes the run)
B29: Finishes | C29: 13 km E, final 3 km @ STEADY (= last 3/13 of the run at STEADY)
B30: Strides | C30: 4 km E + 4 x 20 s strides
B31: Plain runs | C31: E continuous run, Very relaxed recovery run, Long run conversational throughout: any wording without a zone is easy.
B32: Race | C32: Session type Race: the race distance, at goal pace.
B33: Warm-ups | C33: Rep and tempo sessions get an easy warm-up and cool-down added automatically (at least 1.5 km each).
B34: Distances | C34: Write km for a mid-level runner (~30 km/week). They set the shape; Distance 'auto' sizes each run from the runner's volume.
B36: How volume is scaled
B37: • | C37: 100% in Run weeks = the programme's race-ready volume for the runner's level (Programmes tab).
B38: • | C38: Where they start: their answer to 'How far do you run in a typical week?' (pre-filled from their last 4 weeks of runs when the app has them), kept between the minimum and maximum in Rules. Below race-ready, they build up to it (within the max weekly increase); above it, they ease down to it (Rules: ease down per week). Your weekly % shape, deloads and taper are kept either way.
B39: • | C39: Raced in the last two weeks? Onboarding asks, and if they want it they get an easy first week before week 1. Nothing else adds that week.
B40: • | C40: 'auto' easy runs share whatever volume is left in the week after the long run and the workouts, evenly.
B41: • | C41: Safety: a week is never more than Rules → 'Max weekly increase' above what the runner actually did the week before, and no single run exceeds Rules → 'Longest run' for their level (or the programme's long-run cap).
B42: • | C42: Fewer run days than the programme has sessions? The app drops easy and recovery runs first. More days? It adds easy runs.
B43: • | C43: Rep sessions keep their rep lengths; lower-volume runners get fewer reps so hard running stays a sensible share of their week (Rules: fast, threshold and steady reps max).
B44: • | C44: Rep and tempo sessions get an easy warm-up and cool-down (Rules: warm-up). Other runs share what's left: easy 1, recovery 0.75, shakeout 0.6, progression 1.15, within the Rules' run-length limits.
B45: • | C45: A race date lines the programme up so its last week is race week (early weeks skipped if it's sooner, base weeks repeated first if it's further away). The race is its full distance and isn't counted in the week's %.
...

Sheet Programmes
A1: Programme | B1: Name shown in app | C1: Length (weeks) | D1: After the last week | E1: Runs per week (min) | F1: Runs per week (max) | G1: Lifts per week (min) | H1: Lifts per week (max) | I1: Long-run cap (km) | J1: Weekly volume cap (km) | K1: Race-ready volume: beginner (km/week) | L1: Race-ready volume: intermediate (km/week) | M1: Race-ready volume: advanced (km/week) | N1: Taper weeks | O1: Default split | P1: Description shown in onboarding | Q1: Available to | R1: Weeks written | S1: Sessions written | T1: Also suggested (other splits marked Suggested)
A2: First 5K | B2: First 5K | C2: 8 | D2: Repeat | E2: 3 | F2: 3 | G2: 1 | H2: 2 | I2: 8 | J2: 25 | K2: 15 | N2: 1 | O2: Full body ×2 | P2: Build up to running 5K comfortably, then race it. | Q2: Beginner only | R2: =COUNTIF('Run weeks'!$A$2:$A$401,A2) | S2: =COUNTIF('Run sessions'!$A$2:$A$401,A2)
A3: Faster 5K | B3: Faster 5K | C3: 12 | D3: Repeat | E3: 3 | F3: 5 | G3: 1 | H3: 2 | I3: 12 | J3: 60 | K3: 20 | L3: 30 | M3: 45 | N3: 1 | O3: Full body ×2 | P3: Speed, VO2max and threshold work to lower your 5K time. | Q3: All levels | R3: =COUNTIF('Run weeks'!$A$2:$A$401,A3) | S3: =COUNTIF('Run sessions'!$A$2:$A$401,A3)
A4: Faster 10K | B4: Faster 10K | C4: 12 | D4: Repeat | E4: 3 | F4: 5 | G4: 1 | H4: 5 | I4: 16 | J4: 45 | K4: 20 | L4: 40 | M4: 55 | N4: 1 | O4: Full body ×2 | P4: Sharper speed and threshold work to lower your 10K time. | Q4: All levels | R4: =COUNTIF('Run weeks'!$A$2:$A$401,A4) | S4: =COUNTIF('Run sessions'!$A$2:$A$401,A4)
A5: Half marathon | B5: Half marathon | C5: 12 | D5: Repeat | E5: 3 | F5: 5 | G5: 1 | H5: 2 | I5: 22 | J5: 70 | K5: 25 | L5: 40 | M5: 55 | N5: 2 | O5: Full body ×2 | P5: Aerobic base, threshold and a long run that builds to race distance. | Q5: All levels | R5: =COUNTIF('Run weeks'!$A$2:$A$401,A5) | S5: =COUNTIF('Run sessions'!$A$2:$A$401,A5)
A6: Marathon | B6: Marathon | C6: 16 | D6: Repeat | E6: 4 | F6: 6 | G6: 1 | H6: 2 | I6: 32 | J6: 100 | K6: 50 | L6: 75 | M6: 85 | N6: 2 | O6: Full body ×2 | P6: Volume, long runs and marathon-pace work, with a three-week taper. | Q6: All levels | R6: =COUNTIF('Run weeks'!$A$2:$A$401,A6) | S6: =COUNTIF('Run sessions'!$A$2:$A$401,A6)
A7: Build strength | B7: Build strength | C7: 8 | D7: Repeat | E7: 1 | F7: 3 | G7: 2 | H7: 4 | I7: 10 | J7: 25 | K7: 10 | L7: 15 | M7: 25 | N7: 1 | O7: Upper / Lower | P7: Heavy compound lifts with enough running to keep your engine. | Q7: All levels | R7: =COUNTIF('Run weeks'!$A$2:$A$401,A7) | S7: =COUNTIF('Run sessions'!$A$2:$A$401,A7)
A8: Build muscle | B8: Build muscle | C8: 8 | D8: Repeat | E8: 1 | F8: 3 | G8: 3 | H8: 5 | I8: 10 | J8: 25 | K8: 10 | L8: 15 | M8: 25 | N8: 1 | O8: Push / Pull / Legs | P8: Hypertrophy-focused lifting with easy aerobic running. | Q8: All levels | R8: =COUNTIF('Run weeks'!$A$2:$A$401,A8) | S8: =COUNTIF('Run sessions'!$A$2:$A$401,A8) | T8: Push / Pull / Legs / Upper
A9: Balanced hybrid | B9: Balanced hybrid | C9: 8 | D9: Repeat | E9: 2 | F9: 4 | G9: 2 | H9: 3 | I9: 16 | J9: 35 | K9: 15 | L9: 25 | M9: 40 | N9: 1 | O9: Full body ×3 | P9: Run and lift in balance: get faster and stronger together. | Q9: All levels | R9: =COUNTIF('Run weeks'!$A$2:$A$401,A9) | S9: =COUNTIF('Run sessions'!$A$2:$A$401,A9)
A10: Hyrox | B10: Hyrox | C10: 12 | D10: Repeat | E10: 3 | F10: 5 | G10: 2 | H10: 3 | I10: 16 | J10: 55 | K10: 20 | L10: 30 | M10: 45 | N10: 1 | O10: Hyrox: strength + stations | P10: Running, strength and station work for your Hyrox race, with compromised runs and a race simulation. | Q10: All levels | R10: =COUNTIF('Run weeks'!$A$2:$A$401,A10) | S10: =COUNTIF('Run sessions'!$A$2:$A$401,A10)
A12: Programme names in column A are fixed (they match the onboarding goals). Values shown are the app's current defaults.

Sheet Run weeks
A1: Programme | B1: Week | C1: Phase | D1: Volume (% of race-ready) | E1: Long run | F1: Strength emphasis | G1: Notes for the runner | H1: Sessions written | I1: Example: week km | J1: Example: long run km
A2: Half marathon | B2: 1 | C2: Base | D2: 1 | E2: auto | F2: Normal | G2: Settle in: everything easy except one short tempo. | H2: =IF(A2="","",COUNTIFS('Run sessions'!$A$2:$A$401,A2,'Run sessions'!$B$2:$B$401,B2)) | I2: =IF(OR(A2="",D2=""),"",IFERROR(ROUND(D2*IF(INDEX(Programmes!$L$2:$L$10,MATCH(A2,Programmes!$A$2:$A$10,0))="",INDEX(Programmes!$K$2:$K$10,MATCH(A2,Programmes!$A$2:$A$10,0)),INDEX(Programmes!$L$2:$L$10,MATCH(A2,Programmes!$A$2:$A$10,0))),1),"")) | J2: =IF(I2="","",IF(LOWER(E2)="auto",ROUND(I2*Rules!$C$8,1),IF(RIGHT(E2,1)="%",ROUND(I2*VALUE(LEFT(E2,LEN(E2)-1))/100,1),IF(RIGHT(LOWER(E2),2)="km",VALUE(LEFT(E2,LEN(E2)-2)),IF(LOWER(E2)="race","race",E2)))))
A3: Half marathon | B3: 2 | C3: Base | D3: 1.05 | E3: auto | F3: Normal | H3: =IF(A3="","",COUNTIFS('Run sessions'!$A$2:$A$401,A3,'Run sessions'!$B$2:$B$401,B3)) | I3: =IF(OR(A3="",D3=""),"",IFERROR(ROUND(D3*IF(INDEX(Programmes!$L$2:$L$10,MATCH(A3,Programmes!$A$2:$A$10,0))="",INDEX(Programmes!$K$2:$K$10,MATCH(A3,Programmes!$A$2:$A$10,0)),INDEX(Programmes!$L$2:$L$10,MATCH(A3,Programmes!$A$2:$A$10,0))),1),"")) | J3: =IF(I3="","",IF(LOWER(E3)="auto",ROUND(I3*Rules!$C$8,1),IF(RIGHT(E3,1)="%",ROUND(I3*VALUE(LEFT(E3,LEN(E3)-1))/100,1),IF(RIGHT(LOWER(E3),2)="km",VALUE(LEFT(E3,LEN(E3)-2)),IF(LOWER(E3)="race","race",E3)))))
A4: Half marathon | B4: 3 | C4: Base | D4: 1.1 | E4: auto | F4: Heavy | H4: =IF(A4="","",COUNTIFS('Run sessions'!$A$2:$A$401,A4,'Run sessions'!$B$2:$B$401,B4)) | I4: =IF(OR(A4="",D4=""),"",IFERROR(ROUND(D4*IF(INDEX(Programmes!$L$2:$L$10,MATCH(A4,Programmes!$A$2:$A$10,0))="",INDEX(Programmes!$K$2:$K$10,MATCH(A4,Programmes!$A$2:$A$10,0)),INDEX(Programmes!$L$2:$L$10,MATCH(A4,Programmes!$A$2:$A$10,0))),1),"")) | J4: =IF(I4="","",IF(LOWER(E4)="auto",ROUND(I4*Rules!$C$8,1),IF(RIGHT(E4,1)="%",ROUND(I4*VALUE(LEFT(E4,LEN(E4)-1))/100,1),IF(RIGHT(LOWER(E4),2)="km",VALUE(LEFT(E4,LEN(E4)-2)),IF(LOWER(E4)="race","race",E4)))))
A5: Half marathon | B5: 4 | C5: Deload | D5: 0.9 | E5: auto | F5: Light | G5: Lighter week: let the work sink in. | H5: =IF(A5="","",COUNTIFS('Run sessions'!$A$2:$A$401,A5,'Run sessions'!$B$2:$B$401,B5)) | I5: =IF(OR(A5="",D5=""),"",IFERROR(ROUND(D5*IF(INDEX(Programmes!$L$2:$L$10,MATCH(A5,Programmes!$A$2:$A$10,0))="",INDEX(Programmes!$K$2:$K$10,MATCH(A5,Programmes!$A$2:$A$10,0)),INDEX(Programmes!$L$2:$L$10,MATCH(A5,Programmes!$A$2:$A$10,0))),1),"")) | J5: =IF(I5="","",IF(LOWER(E5)="auto",ROUND(I5*Rules!$C$8,1),IF(RIGHT(E5,1)="%",ROUND(I5*VALUE(LEFT(E5,LEN(E5)-1))/100,1),IF(RIGHT(LOWER(E5),2)="km",VALUE(LEFT(E5,LEN(E5)-2)),IF(LOWER(E5)="race","race",E5)))))
A6: Half marathon | B6: 5 | C6: Build | D6: 1.15 | E6: auto | F6: Normal | H6: =IF(A6="","",COUNTIFS('Run sessions'!$A$2:$A$401,A6,'Run sessions'!$B$2:$B$401,B6)) | I6: =IF(OR(A6="",D6=""),"",IFERROR(ROUND(D6*IF(INDEX(Programmes!$L$2:$L$10,MATCH(A6,Programmes!$A$2:$A$10,0))="",INDEX(Programmes!$K$2:$K$10,MATCH(A6,Programmes!$A$2:$A$10,0)),INDEX(Programmes!$L$2:$L$10,MATCH(A6,Programmes!$A$2:$A$10,0))),1),"")) | J6: =IF(I6="","",IF(LOWER(E6)="auto",ROUND(I6*Rules!$C$8,1),IF(RIGHT(E6,1)="%",ROUND(I6*VALUE(LEFT(E6,LEN(E6)-1))/100,1),IF(RIGHT(LOWER(E6),2)="km",VALUE(LEFT(E6,LEN(E6)-2)),IF(LOWER(E6)="race","race",E6)))))
A7: Half marathon | B7: 6 | C7: Build | D7: 1.2 | E7: auto | F7: Heavy | H7: =IF(A7="","",COUNTIFS('Run sessions'!$A$2:$A$401,A7,'Run sessions'!$B$2:$B$401,B7)) | I7: =IF(OR(A7="",D7=""),"",IFERROR(ROUND(D7*IF(INDEX(Programmes!$L$2:$L$10,MATCH(A7,Programmes!$A$2:$A$10,0))="",INDEX(Programmes!$K$2:$K$10,MATCH(A7,Programmes!$A$2:$A$10,0)),INDEX(Programmes!$L$2:$L$10,MATCH(A7,Programmes!$A$2:$A$10,0))),1),"")) | J7: =IF(I7="","",IF(LOWER(E7)="auto",ROUND(I7*Rules!$C$8,1),IF(RIGHT(E7,1)="%",ROUND(I7*VALUE(LEFT(E7,LEN(E7)-1))/100,1),IF(RIGHT(LOWER(E7),2)="km",VALUE(LEFT(E7,LEN(E7)-2)),IF(LOWER(E7)="race","race",E7)))))
A8: Half marathon | B8: 7 | C8: Build | D8: 1.25 | E8: auto | F8: Normal | H8: =IF(A8="","",COUNTIFS('Run sessions'!$A$2:$A$401,A8,'Run sessions'!$B$2:$B$401,B8)) | I8: =IF(OR(A8="",D8=""),"",IFERROR(ROUND(D8*IF(INDEX(Programmes!$L$2:$L$10,MATCH(A8,Programmes!$A$2:$A$10,0))="",INDEX(Programmes!$K$2:$K$10,MATCH(A8,Programmes!$A$2:$A$10,0)),INDEX(Programmes!$L$2:$L$10,MATCH(A8,Programmes!$A$2:$A$10,0))),1),"")) | J8: =IF(I8="","",IF(LOWER(E8)="auto",ROUND(I8*Rules!$C$8,1),IF(RIGHT(E8,1)="%",ROUND(I8*VALUE(LEFT(E8,LEN(E8)-1))/100,1),IF(RIGHT(LOWER(E8),2)="km",VALUE(LEFT(E8,LEN(E8)-2)),IF(LOWER(E8)="race","race",E8)))))
A9: Half marathon | B9: 8 | C9: Deload | D9: 1 | E9: auto | F9: Light | H9: =IF(A9="","",COUNTIFS('Run sessions'!$A$2:$A$401,A9,'Run sessions'!$B$2:$B$401,B9)) | I9: =IF(OR(A9="",D9=""),"",IFERROR(ROUND(D9*IF(INDEX(Programmes!$L$2:$L$10,MATCH(A9,Programmes!$A$2:$A$10,0))="",INDEX(Programmes!$K$2:$K$10,MATCH(A9,Programmes!$A$2:$A$10,0)),INDEX(Programmes!$L$2:$L$10,MATCH(A9,Programmes!$A$2:$A$10,0))),1),"")) | J9: =IF(I9="","",IF(LOWER(E9)="auto",ROUND(I9*Rules!$C$8,1),IF(RIGHT(E9,1)="%",ROUND(I9*VALUE(LEFT(E9,LEN(E9)-1))/100,1),IF(RIGHT(LOWER(E9),2)="km",VALUE(LEFT(E9,LEN(E9)-2)),IF(LOWER(E9)="race","race",E9)))))
A10: Half marathon | B10: 9 | C10: Peak | D10: 1.3 | E10: 18km | F10: Normal | G10: Biggest week. | H10: =IF(A10="","",COUNTIFS('Run sessions'!$A$2:$A$401,A10,'Run sessions'!$B$2:$B$401,B10)) | I10: =IF(OR(A10="",D10=""),"",IFERROR(ROUND(D10*IF(INDEX(Programmes!$L$2:$L$10,MATCH(A10,Programmes!$A$2:$A$10,0))="",INDEX(Programmes!$K$2:$K$10,MATCH(A10,Programmes!$A$2:$A$10,0)),INDEX(Programmes!$L$2:$L$10,MATCH(A10,Programmes!$A$2:$A$10,0))),1),"")) | J10: =IF(I10="","",IF(LOWER(E10)="auto",ROUND(I10*Rules!$C$8,1),IF(RIGHT(E10,1)="%",ROUND(I10*VALUE(LEFT(E10,LEN(E10)-1))/100,1),IF(RIGHT(LOWER(E10),2)="km",VALUE(LEFT(E10,LEN(E10)-2)),IF(LOWER(E10)="race","race",E10)))))
A11: Half marathon | B11: 10 | C11: Peak | D11: 1.3 | E11: auto | F11: Normal | H11: =IF(A11="","",COUNTIFS('Run sessions'!$A$2:$A$401,A11,'Run sessions'!$B$2:$B$401,B11)) | I11: =IF(OR(A11="",D11=""),"",IFERROR(ROUND(D11*IF(INDEX(Programmes!$L$2:$L$10,MATCH(A11,Programmes!$A$2:$A$10,0))="",INDEX(Programmes!$K$2:$K$10,MATCH(A11,Programmes!$A$2:$A$10,0)),INDEX(Programmes!$L$2:$L$10,MATCH(A11,Programmes!$A$2:$A$10,0))),1),"")) | J11: =IF(I11="","",IF(LOWER(E11)="auto",ROUND(I11*Rules!$C$8,1),IF(RIGHT(E11,1)="%",ROUND(I11*VALUE(LEFT(E11,LEN(E11)-1))/100,1),IF(RIGHT(LOWER(E11),2)="km",VALUE(LEFT(E11,LEN(E11)-2)),IF(LOWER(E11)="race","race",E11)))))
A12: Half marathon | B12: 11 | C12: Taper | D12: 0.85 | E12: auto | F12: Light | G12: Freshen up. | H12: =IF(A12="","",COUNTIFS('Run sessions'!$A$2:$A$401,A12,'Run sessions'!$B$2:$B$401,B12)) | I12: =IF(OR(A12="",D12=""),"",IFERROR(ROUND(D12*IF(INDEX(Programmes!$L$2:$L$10,MATCH(A12,Programmes!$A$2:$A$10,0))="",INDEX(Programmes!$K$2:$K$10,MATCH(A12,Programmes!$A$2:$A$10,0)),INDEX(Programmes!$L$2:$L$10,MATCH(A12,Programmes!$A$2:$A$10,0))),1),"")) | J12: =IF(I12="","",IF(LOWER(E12)="auto",ROUND(I12*Rules!$C$8,1),IF(RIGHT(E12,1)="%",ROUND(I12*VALUE(LEFT(E12,LEN(E12)-1))/100,1),IF(RIGHT(LOWER(E12),2)="km",VALUE(LEFT(E12,LEN(E12)-2)),IF(LOWER(E12)="race","race",E12)))))
A13: Half marathon | B13: 12 | C13: Race week | D13: 0.55 | E13: Race | F13: None | G13: Race day! | H13: =IF(A13="","",COUNTIFS('Run sessions'!$A$2:$A$401,A13,'Run sessions'!$B$2:$B$401,B13)) | I13: =IF(OR(A13="",D13=""),"",IFERROR(ROUND(D13*IF(INDEX(Programmes!$L$2:$L$10,MATCH(A13,Programmes!$A$2:$A$10,0))="",INDEX(Programmes!$K$2:$K$10,MATCH(A13,Programmes!$A$2:$A$10,0)),INDEX(Programmes!$L$2:$L$10,MATCH(A13,Programmes!$A$2:$A$10,0))),1),"")) | J13: =IF(I13="","",IF(LOWER(E13)="auto",ROUND(I13*Rules!$C$8,1),IF(RIGHT(E13,1)="%",ROUND(I13*VALUE(LEFT(E13,LEN(E13)-1))/100,1),IF(RIGHT(LOWER(E13),2)="km",VALUE(LEFT(E13,LEN(E13)-2)),IF(LOWER(E13)="race","race",E13)))))
A14: Hyrox | B14: 1 | C14: Base | D14: 0.85 | E14: auto | F14: Normal | G14: Settle in: compromised runs start short, everything else easy. | H14: =IF(A14="","",COUNTIFS('Run sessions'!$A$2:$A$401,A14,'Run sessions'!$B$2:$B$401,B14)) | I14: =IF(OR(A14="",D14=""),"",IFERROR(ROUND(D14*IF(INDEX(Programmes!$L$2:$L$10,MATCH(A14,Programmes!$A$2:$A$10,0))="",INDEX(Programmes!$K$2:$K$10,MATCH(A14,Programmes!$A$2:$A$10,0)),INDEX(Programmes!$L$2:$L$10,MATCH(A14,Programmes!$A$2:$A$10,0))),1),"")) | J14: =IF(I14="","",IF(LOWER(E14)="auto",ROUND(I14*Rules!$C$8,1),IF(RIGHT(E14,1)="%",ROUND(I14*VALUE(LEFT(E14,LEN(E14)-1))/100,1),IF(RIGHT(LOWER(E14),2)="km",VALUE(LEFT(E14,LEN(E14)-2)),IF(LOWER(E14)="race","race",E14)))))
A15: Hyrox | B15: 2 | C15: Base | D15: 0.9 | E15: auto | F15: Normal | H15: =IF(A15="","",COUNTIFS('Run sessions'!$A$2:$A$401,A15,'Run sessions'!$B$2:$B$401,B15)) | I15: =IF(OR(A15="",D15=""),"",IFERROR(ROUND(D15*IF(INDEX(Programmes!$L$2:$L$10,MATCH(A15,Programmes!$A$2:$A$10,0))="",INDEX(Programmes!$K$2:$K$10,MATCH(A15,Programmes!$A$2:$A$10,0)),INDEX(Programmes!$L$2:$L$10,MATCH(A15,Programmes!$A$2:$A$10,0))),1),"")) | J15: =IF(I15="","",IF(LOWER(E15)="auto",ROUND(I15*Rules!$C$8,1),IF(RIGHT(E15,1)="%",ROUND(I15*VALUE(LEFT(E15,LEN(E15)-1))/100,1),IF(RIGHT(LOWER(E15),2)="km",VALUE(LEFT(E15,LEN(E15)-2)),IF(LOWER(E15)="race","race",E15)))))
A16: Hyrox | B16: 3 | C16: Base | D16: 0.95 | E16: auto | F16: Heavy | H16: =IF(A16="","",COUNTIFS('Run sessions'!$A$2:$A$401,A16,'Run sessions'!$B$2:$B$401,B16)) | I16: =IF(OR(A16="",D16=""),"",IFERROR(ROUND(D16*IF(INDEX(Programmes!$L$2:$L$10,MATCH(A16,Programmes!$A$2:$A$10,0))="",INDEX(Programmes!$K$2:$K$10,MATCH(A16,Programmes!$A$2:$A$10,0)),INDEX(Programmes!$L$2:$L$10,MATCH(A16,Programmes!$A$2:$A$10,0))),1),"")) | J16: =IF(I16="","",IF(LOWER(E16)="auto",ROUND(I16*Rules!$C$8,1),IF(RIGHT(E16,1)="%",ROUND(I16*VALUE(LEFT(E16,LEN(E16)-1))/100,1),IF(RIGHT(LOWER(E16),2)="km",VALUE(LEFT(E16,LEN(E16)-2)),IF(LOWER(E16)="race","race",E16)))))
A17: Hyrox | B17: 4 | C17: Deload | D17: 0.8 | E17: auto | F17: Light | G17: Lighter week: let the work sink in. | H17: =IF(A17="","",COUNTIFS('Run sessions'!$A$2:$A$401,A17,'Run sessions'!$B$2:$B$401,B17)) | I17: =IF(OR(A17="",D17=""),"",IFERROR(ROUND(D17*IF(INDEX(Programmes!$L$2:$L$10,MATCH(A17,Programmes!$A$2:$A$10,0))="",INDEX(Programmes!$K$2:$K$10,MATCH(A17,Programmes!$A$2:$A$10,0)),INDEX(Programmes!$L$2:$L$10,MATCH(A17,Programmes!$A$2:$A$10,0))),1),"")) | J17: =IF(I17="","",IF(LOWER(E17)="auto",ROUND(I17*Rules!$C$8,1),IF(RIGHT(E17,1)="%",ROUND(I17*VALUE(LEFT(E17,LEN(E17)-1))/100,1),IF(RIGHT(LOWER(E17),2)="km",VALUE(LEFT(E17,LEN(E17)-2)),IF(LOWER(E17)="race","race",E17)))))
A18: Hyrox | B18: 5 | C18: Build | D18: 1 | E18: auto | F18: Normal | G18: Station weights move towards race weight. | H18: =IF(A18="","",COUNTIFS('Run sessions'!$A$2:$A$401,A18,'Run sessions'!$B$2:$B$401,B18)) | I18: =IF(OR(A18="",D18=""),"",IFERROR(ROUND(D18*IF(INDEX(Programmes!$L$2:$L$10,MATCH(A18,Programmes!$A$2:$A$10,0))="",INDEX(Programmes!$K$2:$K$10,MATCH(A18,Programmes!$A$2:$A$10,0)),INDEX(Programmes!$L$2:$L$10,MATCH(A18,Programmes!$A$2:$A$10,0))),1),"")) | J18: =IF(I18="","",IF(LOWER(E18)="auto",ROUND(I18*Rules!$C$8,1),IF(RIGHT(E18,1)="%",ROUND(I18*VALUE(LEFT(E18,LEN(E18)-1))/100,1),IF(RIGHT(LOWER(E18),2)="km",VALUE(LEFT(E18,LEN(E18)-2)),IF(LOWER(E18)="race","race",E18)))))
A19: Hyrox | B19: 6 | C19: Build | D19: 1.05 | E19: auto | F19: Heavy | H19: =IF(A19="","",COUNTIFS('Run sessions'!$A$2:$A$401,A19,'Run sessions'!$B$2:$B$401,B19)) | I19: =IF(OR(A19="",D19=""),"",IFERROR(ROUND(D19*IF(INDEX(Programmes!$L$2:$L$10,MATCH(A19,Programmes!$A$2:$A$10,0))="",INDEX(Programmes!$K$2:$K$10,MATCH(A19,Programmes!$A$2:$A$10,0)),INDEX(Programmes!$L$2:$L$10,MATCH(A19,Programmes!$A$2:$A$10,0))),1),"")) | J19: =IF(I19="","",IF(LOWER(E19)="auto",ROUND(I19*Rules!$C$8,1),IF(RIGHT(E19,1)="%",ROUND(I19*VALUE(LEFT(E19,LEN(E19)-1))/100,1),IF(RIGHT(LOWER(E19),2)="km",VALUE(LEFT(E19,LEN(E19)-2)),IF(LOWER(E19)="race","race",E19)))))
A20: Hyrox | B20: 7 | C20: Build | D20: 1.1 | E20: auto | F20: Normal | G20: First full 8 km of compromised running. | H20: =IF(A20="","",COUNTIFS('Run sessions'!$A$2:$A$401,A20,'Run sessions'!$B$2:$B$401,B20)) | I20: =IF(OR(A20="",D20=""),"",IFERROR(ROUND(D20*IF(INDEX(Programmes!$L$2:$L$10,MATCH(A20,Programmes!$A$2:$A$10,0))="",INDEX(Programmes!$K$2:$K$10,MATCH(A20,Programmes!$A$2:$A$10,0)),INDEX(Programmes!$L$2:$L$10,MATCH(A20,Programmes!$A$2:$A$10,0))),1),"")) | J20: =IF(I20="","",IF(LOWER(E20)="auto",ROUND(I20*Rules!$C$8,1),IF(RIGHT(E20,1)="%",ROUND(I20*VALUE(LEFT(E20,LEN(E20)-1))/100,1),IF(RIGHT(LOWER(E20),2)="km",VALUE(LEFT(E20,LEN(E20)-2)),IF(LOWER(E20)="race","race",E20)))))
A21: Hyrox | B21: 8 | C21: Deload | D21: 0.9 | E21: auto | F21: Light | G21: Lighter week before the race block. | H21: =IF(A21="","",COUNTIFS('Run sessions'!$A$2:$A$401,A21,'Run sessions'!$B$2:$B$401,B21)) | I21: =IF(OR(A21="",D21=""),"",IFERROR(ROUND(D21*IF(INDEX(Programmes!$L$2:$L$10,MATCH(A21,Programmes!$A$2:$A$10,0))="",INDEX(Programmes!$K$2:$K$10,MATCH(A21,Programmes!$A$2:$A$10,0)),INDEX(Programmes!$L$2:$L$10,MATCH(A21,Programmes!$A$2:$A$10,0))),1),"")) | J21: =IF(I21="","",IF(LOWER(E21)="auto",ROUND(I21*Rules!$C$8,1),IF(RIGHT(E21,1)="%",ROUND(I21*VALUE(LEFT(E21,LEN(E21)-1))/100,1),IF(RIGHT(LOWER(E21),2)="km",VALUE(LEFT(E21,LEN(E21)-2)),IF(LOWER(E21)="race","race",E21)))))
A22: Hyrox | B22: 9 | C22: Peak | D22: 1.1 | E22: auto | F22: Normal | G22: Race simulation: run it like race day, all eight stations. | H22: =IF(A22="","",COUNTIFS('Run sessions'!$A$2:$A$401,A22,'Run sessions'!$B$2:$B$401,B22)) | I22: =IF(OR(A22="",D22=""),"",IFERROR(ROUND(D22*IF(INDEX(Programmes!$L$2:$L$10,MATCH(A22,Programmes!$A$2:$A$10,0))="",INDEX(Programmes!$K$2:$K$10,MATCH(A22,Programmes!$A$2:$A$10,0)),INDEX(Programmes!$L$2:$L$10,MATCH(A22,Programmes!$A$2:$A$10,0))),1),"")) | J22: =IF(I22="","",IF(LOWER(E22)="auto",ROUND(I22*Rules!$C$8,1),IF(RIGHT(E22,1)="%",ROUND(I22*VALUE(LEFT(E22,LEN(E22)-1))/100,1),IF(RIGHT(LOWER(E22),2)="km",VALUE(LEFT(E22,LEN(E22)-2)),IF(LOWER(E22)="race","race",E22)))))
A23: Hyrox | B23: 10 | C23: Peak | D23: 1.1 | E23: auto | F23: Normal | G23: Biggest week. | H23: =IF(A23="","",COUNTIFS('Run sessions'!$A$2:$A$401,A23,'Run sessions'!$B$2:$B$401,B23)) | I23: =IF(OR(A23="",D23=""),"",IFERROR(ROUND(D23*IF(INDEX(Programmes!$L$2:$L$10,MATCH(A23,Programmes!$A$2:$A$10,0))="",INDEX(Programmes!$K$2:$K$10,MATCH(A23,Programmes!$A$2:$A$10,0)),INDEX(Programmes!$L$2:$L$10,MATCH(A23,Programmes!$A$2:$A$10,0))),1),"")) | J23: =IF(I23="","",IF(LOWER(E23)="auto",ROUND(I23*Rules!$C$8,1),IF(RIGHT(E23,1)="%",ROUND(I23*VALUE(LEFT(E23,LEN(E23)-1))/100,1),IF(RIGHT(LOWER(E23),2)="km",VALUE(LEFT(E23,LEN(E23)-2)),IF(LOWER(E23)="race","race",E23)))))
A24: Hyrox | B24: 11 | C24: Taper | D24: 0.8 | E24: auto | F24: Light | G24: Freshen up: shorter, sharper sessions. | H24: =IF(A24="","",COUNTIFS('Run sessions'!$A$2:$A$401,A24,'Run sessions'!$B$2:$B$401,B24)) | I24: =IF(OR(A24="",D24=""),"",IFERROR(ROUND(D24*IF(INDEX(Programmes!$L$2:$L$10,MATCH(A24,Programmes!$A$2:$A$10,0))="",INDEX(Programmes!$K$2:$K$10,MATCH(A24,Programmes!$A$2:$A$10,0)),INDEX(Programmes!$L$2:$L$10,MATCH(A24,Programmes!$A$2:$A$10,0))),1),"")) | J24: =IF(I24="","",IF(LOWER(E24)="auto",ROUND(I24*Rules!$C$8,1),IF(RIGHT(E24,1)="%",ROUND(I24*VALUE(LEFT(E24,LEN(E24)-1))/100,1),IF(RIGHT(LOWER(E24),2)="km",VALUE(LEFT(E24,LEN(E24)-2)),IF(LOWER(E24)="race","race",E24)))))
A25: Hyrox | B25: 12 | C25: Race week | D25: 0.5 | E25: Race | F25: None | G25: Race day! Pace the first kilometre. | H25: =IF(A25="","",COUNTIFS('Run sessions'!$A$2:$A$401,A25,'Run sessions'!$B$2:$B$401,B25)) | I25: =IF(OR(A25="",D25=""),"",IFERROR(ROUND(D25*IF(INDEX(Programmes!$L$2:$L$10,MATCH(A25,Programmes!$A$2:$A$10,0))="",INDEX(Programmes!$K$2:$K$10,MATCH(A25,Programmes!$A$2:$A$10,0)),INDEX(Programmes!$L$2:$L$10,MATCH(A25,Programmes!$A$2:$A$10,0))),1),"")) | J25: =IF(I25="","",IF(LOWER(E25)="auto",ROUND(I25*Rules!$C$8,1),IF(RIGHT(E25,1)="%",ROUND(I25*VALUE(LEFT(E25,LEN(E25)-1))/100,1),IF(RIGHT(LOWER(E25),2)="km",VALUE(LEFT(E25,LEN(E25)-2)),IF(LOWER(E25)="race","race",E25)))))
A26: Faster 10K | B26: 1 | C26: Base | D26: 1 | E26: auto | F26: Normal | G26: Settle in: one quality session, the rest easy. | H26: =IF(A26="","",COUNTIFS('Run sessions'!$A$2:$A$401,A26,'Run sessions'!$B$2:$B$401,B26)) | I26: =IF(OR(A26="",D26=""),"",IFERROR(ROUND(D26*IF(INDEX(Programmes!$L$2:$L$10,MATCH(A26,Programmes!$A$2:$A$10,0))="",INDEX(Programmes!$K$2:$K$10,MATCH(A26,Programmes!$A$2:$A$10,0)),INDEX(Programmes!$L$2:$L$10,MATCH(A26,Programmes!$A$2:$A$10,0))),1),"")) | J26: =IF(I26="","",IF(LOWER(E26)="auto",ROUND(I26*Rules!$C$8,1),IF(RIGHT(E26,1)="%",ROUND(I26*VALUE(LEFT(E26,LEN(E26)-1))/100,1),IF(RIGHT(LOWER(E26),2)="km",VALUE(LEFT(E26,LEN(E26)-2)),IF(LOWER(E26)="race","race",E26)))))
A27: Faster 10K | B27: 2 | C27: Base | D27: 1.05 | E27: auto | F27: Normal | H27: =IF(A27="","",COUNTIFS('Run sessions'!$A$2:$A$401,A27,'Run sessions'!$B$2:$B$401,B27)) | I27: =IF(OR(A27="",D27=""),"",IFERROR(ROUND(D27*IF(INDEX(Programmes!$L$2:$L$10,MATCH(A27,Programmes!$A$2:$A$10,0))="",INDEX(Programmes!$K$2:$K$10,MATCH(A27,Programmes!$A$2:$A$10,0)),INDEX(Programmes!$L$2:$L$10,MATCH(A27,Programmes!$A$2:$A$10,0))),1),"")) | J27: =IF(I27="","",IF(LOWER(E27)="auto",ROUND(I27*Rules!$C$8,1),IF(RIGHT(E27,1)="%",ROUND(I27*VALUE(LEFT(E27,LEN(E27)-1))/100,1),IF(RIGHT(LOWER(E27),2)="km",VALUE(LEFT(E27,LEN(E27)-2)),IF(LOWER(E27)="race","race",E27)))))
A28: Faster 10K | B28: 3 | C28: Base | D28: 1.1 | E28: auto | F28: Heavy | H28: =IF(A28="","",COUNTIFS('Run sessions'!$A$2:$A$401,A28,'Run sessions'!$B$2:$B$401,B28)) | I28: =IF(OR(A28="",D28=""),"",IFERROR(ROUND(D28*IF(INDEX(Programmes!$L$2:$L$10,MATCH(A28,Programmes!$A$2:$A$10,0))="",INDEX(Programmes!$K$2:$K$10,MATCH(A28,Programmes!$A$2:$A$10,0)),INDEX(Programmes!$L$2:$L$10,MATCH(A28,Programmes!$A$2:$A$10,0))),1),"")) | J28: =IF(I28="","",IF(LOWER(E28)="auto",ROUND(I28*Rules!$C$8,1),IF(RIGHT(E28,1)="%",ROUND(I28*VALUE(LEFT(E28,LEN(E28)-1))/100,1),IF(RIGHT(LOWER(E28),2)="km",VALUE(LEFT(E28,LEN(E28)-2)),IF(LOWER(E28)="race","race",E28)))))
A29: Faster 10K | B29: 4 | C29: Deload | D29: 0.9 | E29: auto | F29: Light | G29: Lighter week: let the work sink in. | H29: =IF(A29="","",COUNTIFS('Run sessions'!$A$2:$A$401,A29,'Run sessions'!$B$2:$B$401,B29)) | I29: =IF(OR(A29="",D29=""),"",IFERROR(ROUND(D29*IF(INDEX(Programmes!$L$2:$L$10,MATCH(A29,Programmes!$A$2:$A$10,0))="",INDEX(Programmes!$K$2:$K$10,MATCH(A29,Programmes!$A$2:$A$10,0)),INDEX(Programmes!$L$2:$L$10,MATCH(A29,Programmes!$A$2:$A$10,0))),1),"")) | J29: =IF(I29="","",IF(LOWER(E29)="auto",ROUND(I29*Rules!$C$8,1),IF(RIGHT(E29,1)="%",ROUND(I29*VALUE(LEFT(E29,LEN(E29)-1))/100,1),IF(RIGHT(LOWER(E29),2)="km",VALUE(LEFT(E29,LEN(E29)-2)),IF(LOWER(E29)="race","race",E29)))))
A30: Faster 10K | B30: 5 | C30: Build | D30: 1.1 | E30: auto | F30: Normal | H30: =IF(A30="","",COUNTIFS('Run sessions'!$A$2:$A$401,A30,'Run sessions'!$B$2:$B$401,B30)) | I30: =IF(OR(A30="",D30=""),"",IFERROR(ROUND(D30*IF(INDEX(Programmes!$L$2:$L$10,MATCH(A30,Programmes!$A$2:$A$10,0))="",INDEX(Programmes!$K$2:$K$10,MATCH(A30,Programmes!$A$2:$A$10,0)),INDEX(Programmes!$L$2:$L$10,MATCH(A30,Programmes!$A$2:$A$10,0))),1),"")) | J30: =IF(I30="","",IF(LOWER(E30)="auto",ROUND(I30*Rules!$C$8,1),IF(RIGHT(E30,1)="%",ROUND(I30*VALUE(LEFT(E30,LEN(E30)-1))/100,1),IF(RIGHT(LOWER(E30),2)="km",VALUE(LEFT(E30,LEN(E30)-2)),IF(LOWER(E30)="race","race",E30)))))
A31: Faster 10K | B31: 6 | C31: Build | D31: 1.15 | E31: auto | F31: Heavy | H31: =IF(A31="","",COUNTIFS('Run sessions'!$A$2:$A$401,A31,'Run sessions'!$B$2:$B$401,B31)) | I31: =IF(OR(A31="",D31=""),"",IFERROR(ROUND(D31*IF(INDEX(Programmes!$L$2:$L$10,MATCH(A31,Programmes!$A$2:$A$10,0))="",INDEX(Programmes!$K$2:$K$10,MATCH(A31,Programmes!$A$2:$A$10,0)),INDEX(Programmes!$L$2:$L$10,MATCH(A31,Programmes!$A$2:$A$10,0))),1),"")) | J31: =IF(I31="","",IF(LOWER(E31)="auto",ROUND(I31*Rules!$C$8,1),IF(RIGHT(E31,1)="%",ROUND(I31*VALUE(LEFT(E31,LEN(E31)-1))/100,1),IF(RIGHT(LOWER(E31),2)="km",VALUE(LEFT(E31,LEN(E31)-2)),IF(LOWER(E31)="race","race",E31)))))
A32: Faster 10K | B32: 7 | C32: Build | D32: 1.2 | E32: auto | F32: Normal | H32: =IF(A32="","",COUNTIFS('Run sessions'!$A$2:$A$401,A32,'Run sessions'!$B$2:$B$401,B32)) | I32: =IF(OR(A32="",D32=""),"",IFERROR(ROUND(D32*IF(INDEX(Programmes!$L$2:$L$10,MATCH(A32,Programmes!$A$2:$A$10,0))="",INDEX(Programmes!$K$2:$K$10,MATCH(A32,Programmes!$A$2:$A$10,0)),INDEX(Programmes!$L$2:$L$10,MATCH(A32,Programmes!$A$2:$A$10,0))),1),"")) | J32: =IF(I32="","",IF(LOWER(E32)="auto",ROUND(I32*Rules!$C$8,1),IF(RIGHT(E32,1)="%",ROUND(I32*VALUE(LEFT(E32,LEN(E32)-1))/100,1),IF(RIGHT(LOWER(E32),2)="km",VALUE(LEFT(E32,LEN(E32)-2)),IF(LOWER(E32)="race","race",E32)))))
A33: Faster 10K | B33: 8 | C33: Deload | D33: 0.95 | E33: auto | F33: Light | G33: Lighter week before the peak. | H33: =IF(A33="","",COUNTIFS('Run sessions'!$A$2:$A$401,A33,'Run sessions'!$B$2:$B$401,B33)) | I33: =IF(OR(A33="",D33=""),"",IFERROR(ROUND(D33*IF(INDEX(Programmes!$L$2:$L$10,MATCH(A33,Programmes!$A$2:$A$10,0))="",INDEX(Programmes!$K$2:$K$10,MATCH(A33,Programmes!$A$2:$A$10,0)),INDEX(Programmes!$L$2:$L$10,MATCH(A33,Programmes!$A$2:$A$10,0))),1),"")) | J33: =IF(I33="","",IF(LOWER(E33)="auto",ROUND(I33*Rules!$C$8,1),IF(RIGHT(E33,1)="%",ROUND(I33*VALUE(LEFT(E33,LEN(E33)-1))/100,1),IF(RIGHT(LOWER(E33),2)="km",VALUE(LEFT(E33,LEN(E33)-2)),IF(LOWER(E33)="race","race",E33)))))
A34: Faster 10K | B34: 9 | C34: Peak | D34: 1.25 | E34: auto | F34: Normal | G34: Biggest week. | H34: =IF(A34="","",COUNTIFS('Run sessions'!$A$2:$A$401,A34,'Run sessions'!$B$2:$B$401,B34)) | I34: =IF(OR(A34="",D34=""),"",IFERROR(ROUND(D34*IF(INDEX(Programmes!$L$2:$L$10,MATCH(A34,Programmes!$A$2:$A$10,0))="",INDEX(Programmes!$K$2:$K$10,MATCH(A34,Programmes!$A$2:$A$10,0)),INDEX(Programmes!$L$2:$L$10,MATCH(A34,Programmes!$A$2:$A$10,0))),1),"")) | J34: =IF(I34="","",IF(LOWER(E34)="auto",ROUND(I34*Rules!$C$8,1),IF(RIGHT(E34,1)="%",ROUND(I34*VALUE(LEFT(E34,LEN(E34)-1))/100,1),IF(RIGHT(LOWER(E34),2)="km",VALUE(LEFT(E34,LEN(E34)-2)),IF(LOWER(E34)="race","race",E34)))))
A35: Faster 10K | B35: 10 | C35: Peak | D35: 1.25 | E35: auto | F35: Normal | H35: =IF(A35="","",COUNTIFS('Run sessions'!$A$2:$A$401,A35,'Run sessions'!$B$2:$B$401,B35)) | I35: =IF(OR(A35="",D35=""),"",IFERROR(ROUND(D35*IF(INDEX(Programmes!$L$2:$L$10,MATCH(A35,Programmes!$A$2:$A$10,0))="",INDEX(Programmes!$K$2:$K$10,MATCH(A35,Programmes!$A$2:$A$10,0)),INDEX(Programmes!$L$2:$L$10,MATCH(A35,Programmes!$A$2:$A$10,0))),1),"")) | J35: =IF(I35="","",IF(LOWER(E35)="auto",ROUND(I35*Rules!$C$8,1),IF(RIGHT(E35,1)="%",ROUND(I35*VALUE(LEFT(E35,LEN(E35)-1))/100,1),IF(RIGHT(LOWER(E35),2)="km",VALUE(LEFT(E35,LEN(E35)-2)),IF(LOWER(E35)="race","race",E35)))))
A36: Faster 10K | B36: 11 | C36: Taper | D36: 0.85 | E36: auto | F36: Light | G36: Freshen up. | H36: =IF(A36="","",COUNTIFS('Run sessions'!$A$2:$A$401,A36,'Run sessions'!$B$2:$B$401,B36)) | I36: =IF(OR(A36="",D36=""),"",IFERROR(ROUND(D36*IF(INDEX(Programmes!$L$2:$L$10,MATCH(A36,Programmes!$A$2:$A$10,0))="",INDEX(Programmes!$K$2:$K$10,MATCH(A36,Programmes!$A$2:$A$10,0)),INDEX(Programmes!$L$2:$L$10,MATCH(A36,Programmes!$A$2:$A$10,0))),1),"")) | J36: =IF(I36="","",IF(LOWER(E36)="auto",ROUND(I36*Rules!$C$8,1),IF(RIGHT(E36,1)="%",ROUND(I36*VALUE(LEFT(E36,LEN(E36)-1))/100,1),IF(RIGHT(LOWER(E36),2)="km",VALUE(LEFT(E36,LEN(E36)-2)),IF(LOWER(E36)="race","race",E36)))))
A37: Faster 10K | B37: 12 | C37: Race week | D37: 0.55 | E37: Race | F37: None | G37: Race day! | H37: =IF(A37="","",COUNTIFS('Run sessions'!$A$2:$A$401,A37,'Run sessions'!$B$2:$B$401,B37)) | I37: =IF(OR(A37="",D37=""),"",IFERROR(ROUND(D37*IF(INDEX(Programmes!$L$2:$L$10,MATCH(A37,Programmes!$A$2:$A$10,0))="",INDEX(Programmes!$K$2:$K$10,MATCH(A37,Programmes!$A$2:$A$10,0)),INDEX(Programmes!$L$2:$L$10,MATCH(A37,Programmes!$A$2:$A$10,0))),1),"")) | J37: =IF(I37="","",IF(LOWER(E37)="auto",ROUND(I37*Rules!$C$8,1),IF(RIGHT(E37,1)="%",ROUND(I37*VALUE(LEFT(E37,LEN(E37)-1))/100,1),IF(RIGHT(LOWER(E37),2)="km",VALUE(LEFT(E37,LEN(E37)-2)),IF(LOWER(E37)="race","race",E37)))))
A38: Marathon | B38: 1 | C38: Base | D38: 1 | E38: auto | F38: Normal | G38: Settle in: one threshold session and an M-pace progression, everything else easy. | H38: =IF(A38="","",COUNTIFS('Run sessions'!$A$2:$A$401,A38,'Run sessions'!$B$2:$B$401,B38)) | I38: =IF(OR(A38="",D38=""),"",IFERROR(ROUND(D38*IF(INDEX(Programmes!$L$2:$L$10,MATCH(A38,Programmes!$A$2:$A$10,0))="",INDEX(Programmes!$K$2:$K$10,MATCH(A38,Programmes!$A$2:$A$10,0)),INDEX(Programmes!$L$2:$L$10,MATCH(A38,Programmes!$A$2:$A$10,0))),1),"")) | J38: =IF(I38="","",IF(LOWER(E38)="auto",ROUND(I38*Rules!$C$8,1),IF(RIGHT(E38,1)="%",ROUND(I38*VALUE(LEFT(E38,LEN(E38)-1))/100,1),IF(RIGHT(LOWER(E38),2)="km",VALUE(LEFT(E38,LEN(E38)-2)),IF(LOWER(E38)="race","race",E38)))))
A39: Marathon | B39: 2 | C39: Base | D39: 1.05 | E39: auto | F39: Normal | H39: =IF(A39="","",COUNTIFS('Run sessions'!$A$2:$A$401,A39,'Run sessions'!$B$2:$B$401,B39)) | I39: =IF(OR(A39="",D39=""),"",IFERROR(ROUND(D39*IF(INDEX(Programmes!$L$2:$L$10,MATCH(A39,Programmes!$A$2:$A$10,0))="",INDEX(Programmes!$K$2:$K$10,MATCH(A39,Programmes!$A$2:$A$10,0)),INDEX(Programmes!$L$2:$L$10,MATCH(A39,Programmes!$A$2:$A$10,0))),1),"")) | J39: =IF(I39="","",IF(LOWER(E39)="auto",ROUND(I39*Rules!$C$8,1),IF(RIGHT(E39,1)="%",ROUND(I39*VALUE(LEFT(E39,LEN(E39)-1))/100,1),IF(RIGHT(LOWER(E39),2)="km",VALUE(LEFT(E39,LEN(E39)-2)),IF(LOWER(E39)="race","race",E39)))))
A40: Marathon | B40: 3 | C40: Base | D40: 1.1 | E40: auto | F40: Normal | H40: =IF(A40="","",COUNTIFS('Run sessions'!$A$2:$A$401,A40,'Run sessions'!$B$2:$B$401,B40)) | I40: =IF(OR(A40="",D40=""),"",IFERROR(ROUND(D40*IF(INDEX(Programmes!$L$2:$L$10,MATCH(A40,Programmes!$A$2:$A$10,0))="",INDEX(Programmes!$K$2:$K$10,MATCH(A40,Programmes!$A$2:$A$10,0)),INDEX(Programmes!$L$2:$L$10,MATCH(A40,Programmes!$A$2:$A$10,0))),1),"")) | J40: =IF(I40="","",IF(LOWER(E40)="auto",ROUND(I40*Rules!$C$8,1),IF(RIGHT(E40,1)="%",ROUND(I40*VALUE(LEFT(E40,LEN(E40)-1))/100,1),IF(RIGHT(LOWER(E40),2)="km",VALUE(LEFT(E40,LEN(E40)-2)),IF(LOWER(E40)="race","race",E40)))))
...

Sheet Run sessions
A1: Programme | B1: Week | C1: Order in week | D1: Session type | E1: Distance | F1: Workout | G1: Notes for the runner
A2: Half marathon | B2: 1 | C2: 1 | D2: Fartlek | E2: auto | F2: 8 x (1 min @ I / 1 min E)
A3: Half marathon | B3: 1 | C3: 2 | D3: Easy | E3: auto | F3: E continuous run
A4: Half marathon | B4: 1 | C4: 3 | D4: Progression | E4: auto | F4: 4 km E → 3 km STEADY → 1 km HM
A5: Half marathon | B5: 1 | C5: 4 | D5: Long | E5: auto | F5: Long run, conversational throughout
A6: Half marathon | B6: 2 | C6: 1 | D6: Hills | E6: auto | F6: 8 x 60 s uphill @ hard effort, jog back down as recovery
A7: Half marathon | B7: 2 | C7: 2 | D7: Recovery | E7: auto | F7: Very relaxed recovery run
A8: Half marathon | B8: 2 | C8: 3 | D8: Tempo | E8: auto | F8: 2 x 8 min @ T, 2 min jog between
A9: Half marathon | B9: 2 | C9: 4 | D9: Long | E9: auto | F9: Long run, conversational throughout
A10: Half marathon | B10: 3 | C10: 1 | D10: Intervals | E10: auto | F10: 6 x 800 m @ I , 90 s jog between
A11: Half marathon | B11: 3 | C11: 2 | D11: Easy | E11: auto | F11: E continuous run
A12: Half marathon | B12: 3 | C12: 3 | D12: Progression | E12: auto | F12: 4 km E → 3 km STEADY → 2 km HM
A13: Half marathon | B13: 3 | C13: 4 | D13: Long | E13: auto | F13: Long run, conversational throughout
... A50: Hyrox | B50: 1 | C50: 1 | D50: Intervals | E50: auto | F50: 5 x 1 km @ T, 90 s jog between
A51: Hyrox | B51: 1 | C51: 2 | D51: Compromised | E51: auto | F51: 4 x 1 km @ HM effort, 2 min station between | G51: Between reps: one station from your list (e.g. 20 wall balls, 250 m row, 25 m sled push), at your division's weight.
A52: Hyrox | B52: 1 | C52: 3 | D52: Easy | E52: auto | F52: E continuous run
A53: Hyrox | B53: 1 | C53: 4 | D53: Long | E53: auto | F53: Long run, conversational throughout
A54: Hyrox | B54: 2 | C54: 1 | D54: Tempo | E54: auto | F54: 3 x 8 min @ T, 2 min jog between
A55: Hyrox | B55: 2 | C55: 2 | D55: Compromised | E55: auto | F55: 5 x 1 km @ HM effort, 2 min station between | G55: Between reps: one station from your list (e.g. 20 wall balls, 250 m row, 25 m sled push), at your division's weight.
A56: Hyrox | B56: 2 | C56: 3 | D56: Easy | E56: auto | F56: E continuous run
A57: Hyrox | B57: 2 | C57: 4 | D57: Long | E57: auto | F57: Long run, conversational throughout
A58: Hyrox | B58: 3 | C58: 1 | D58: Intervals | E58: auto | F58: 6 x 1 km @ T, 90 s jog between
A59: Hyrox | B59: 3 | C59: 2 | D59: Compromised | E59: auto | F59: 6 x 1 km @ HM effort, 2 min station between | G59: Between reps: one station from your list (e.g. 20 wall balls, 250 m row, 25 m sled push), at your division's weight.
A60: Hyrox | B60: 3 | C60: 3 | D60: Easy | E60: auto | F60: E continuous run
A61: Hyrox | B61: 3 | C61: 4 | D61: Long | E61: auto | F61: Long run, conversational throughout
A62: Hyrox | B62: 4 | C62: 1 | D62: Fartlek | E62: auto | F62: 8 x (1 min @ I / 1 min E)
A63: Hyrox | B63: 4 | C63: 2 | D63: Compromised | E63: auto | F63: 4 x 1 km @ HM effort, 2 min station between | G63: Between reps: one station from your list (e.g. 20 wall balls, 250 m row, 25 m sled push), at your division's weight.
A64: Hyrox | B64: 4 | C64: 3 | D64: Long | E64: auto | F64: Long run, conversational throughout
A65: Hyrox | B65: 5 | C65: 1 | D65: Tempo | E65: auto | F65: 20 min continuous @ T
A66: Hyrox | B66: 5 | C66: 2 | D66: Compromised | E66: auto | F66: 6 x 1 km @ HM, 2 min station between | G66: Between reps: one station from your list (e.g. 20 wall balls, 250 m row, 25 m sled push), at your division's weight.
A67: Hyrox | B67: 5 | C67: 3 | D67: Easy | E67: auto | F67: E continuous run
A68: Hyrox | B68: 5 | C68: 4 | D68: Long | E68: auto | F68: Long run, conversational throughout
A69: Hyrox | B69: 6 | C69: 1 | D69: Intervals | E69: auto | F69: 5 x 1 km @ I, 2 min jog between
A70: Hyrox | B70: 6 | C70: 2 | D70: Compromised | E70: auto | F70: 7 x 1 km @ HM, 2 min station between | G70: Between reps: one station from your list (e.g. 20 wall balls, 250 m row, 25 m sled push), at your division's weight.
A71: Hyrox | B71: 6 | C71: 3 | D71: Easy | E71: auto | F71: E continuous run
A72: Hyrox | B72: 6 | C72: 4 | D72: Long | E72: auto | F72: Long run, conversational throughout
A73: Hyrox | B73: 7 | C73: 1 | D73: Tempo | E73: auto | F73: 2 x 12 min @ T, 2 min jog between
A74: Hyrox | B74: 7 | C74: 2 | D74: Compromised | E74: auto | F74: 8 x 1 km @ HM, 2 min station between | G74: Between reps: one station from your list (e.g. 20 wall balls, 250 m row, 25 m sled push), at your division's weight.
A75: Hyrox | B75: 7 | C75: 3 | D75: Easy | E75: auto | F75: E continuous run
A76: Hyrox | B76: 7 | C76: 4 | D76: Long | E76: auto | F76: Long run, conversational throughout
...

Sheet Pace zones
A1: Code | B1: Name | C1: What it's for | D1: How the app sets it | E1: Effort (RPE /10) | F1: Your notes / changes
A2: E | B2: Easy | C2: Conversational. Easy runs, long runs, warm-ups, cool-downs, jog recoveries. | D2: VDOT easy range | E2: 3–4
A3: STEADY | B3: Steady | C3: Between easy and marathon pace: relaxed but purposeful. Steady finishes and progressions. | D3: Marathon pace + 10–20 s/km | E3: 4–5
A4: M | B4: Marathon | C4: Marathon race pace. | D4: VDOT marathon pace | E4: 5–6
A5: HM | B5: Half-Marathon | C5: Half Marathon Pace | D5: VDOT half marathon pace | E5: 5–6
A6: T | B6: Threshold | C6: Comfortably hard; ~1 hour race effort. Tempo runs, cruise intervals. | D6: VDOT threshold pace | E6: 6–7
A7: 10K | B7: 10K | C7: 10K race pace. Longer reps and fartlek surges. | D7: Predicted 10K pace from race time | E7: 7–8
A8: 5K | B8: 5K | C8: 5K race pace. | D8: Predicted 5K pace from race time | E8: 8–9
A9: I | B9: Interval | C9: 3K–5K race effort. VO2max reps of 2–5 minutes. | D9: VDOT interval pace | E9: 8–9
A10: R | B10: Repetition | C10: Mile race effort. Short fast reps with full recovery. | D10: VDOT repetition pace | E10: 9
A12: Paces come from the runner's recent race time (Jack Daniels' VDOT tables) and update as they get fitter. Codes can't be renamed; descriptions can.

Sheet Strength splits
A1: Split | B1: Days per week | C1: Day names (in order) | D1: Who it suits | E1: Shown in onboarding? | F1: Days written
A2: Full body ×1 | B2: 1 | C2: Full body | D2: Very busy weeks or running-focused plans. | E2: Yes | F2: =SUMPRODUCT(('Split days'!$A$2:$A$401=A2)/COUNTIFS('Split days'!$A$2:$A$401,'Split days'!$A$2:$A$401&"",'Split days'!$B$2:$B$401,'Split days'!$B$2:$B$401&""))
A3: Full body ×2 | B3: 2 | C3: Full body A, Full body B | D3: Most runners: two sessions that cover everything. | E3: Yes | F3: =SUMPRODUCT(('Split days'!$A$2:$A$401=A3)/COUNTIFS('Split days'!$A$2:$A$401,'Split days'!$A$2:$A$401&"",'Split days'!$B$2:$B$401,'Split days'!$B$2:$B$401&""))
A4: Full body ×3 | B4: 3 | C4: Full body A, Full body B, Full body C | D4: Balanced hybrid, newer lifters. | E4: Yes | F4: =SUMPRODUCT(('Split days'!$A$2:$A$401=A4)/COUNTIFS('Split days'!$A$2:$A$401,'Split days'!$A$2:$A$401&"",'Split days'!$B$2:$B$401,'Split days'!$B$2:$B$401&""))
A5: Upper / Lower | B5: 4 | C5: Upper A, Lower A, Upper B, Lower B | D5: Strength focus with 4 lifting days. | E5: Yes | F5: =SUMPRODUCT(('Split days'!$A$2:$A$401=A5)/COUNTIFS('Split days'!$A$2:$A$401,'Split days'!$A$2:$A$401&"",'Split days'!$B$2:$B$401,'Split days'!$B$2:$B$401&""))
A6: Push / Pull / Legs | B6: 3 | C6: Push, Pull, Legs | D6: Muscle focus with 3 lifting days. | E6: Yes | F6: =SUMPRODUCT(('Split days'!$A$2:$A$401=A6)/COUNTIFS('Split days'!$A$2:$A$401,'Split days'!$A$2:$A$401&"",'Split days'!$B$2:$B$401,'Split days'!$B$2:$B$401&""))
A7: Push / Pull / Legs ×2 | B7: 6 | C7: Push A, Pull A, Legs A, Push B, Pull B, Legs B | D7: Experienced lifters, muscle focus, light running. | E7: Yes | F7: =SUMPRODUCT(('Split days'!$A$2:$A$401=A7)/COUNTIFS('Split days'!$A$2:$A$401,'Split days'!$A$2:$A$401&"",'Split days'!$B$2:$B$401,'Split days'!$B$2:$B$401&""))
A8: Upper / Lower / Full | B8: 3 | C8: Upper, Lower, Full body | D8: 3 days, a bit more volume per muscle than full body. | E8: Yes | F8: =SUMPRODUCT(('Split days'!$A$2:$A$401=A8)/COUNTIFS('Split days'!$A$2:$A$401,'Split days'!$A$2:$A$401&"",'Split days'!$B$2:$B$401,'Split days'!$B$2:$B$401&""))
A9: PPL + Upper / Lower | B9: 5 | C9: Push, Pull, Legs, Upper, Lower | D9: 5 lifting days, muscle focus. | E9: Yes | F9: =SUMPRODUCT(('Split days'!$A$2:$A$401=A9)/COUNTIFS('Split days'!$A$2:$A$401,'Split days'!$A$2:$A$401&"",'Split days'!$B$2:$B$401,'Split days'!$B$2:$B$401&""))
A10: PPL + Upper + Shoulders & arms | B10: 5 | C10: Push, Pull, Legs, Upper, Shoulders & arms | D10: 5 lifting days, muscle focus. | E10: Yes | F10: =SUMPRODUCT(('Split days'!$A$2:$A$401=A10)/COUNTIFS('Split days'!$A$2:$A$401,'Split days'!$A$2:$A$401&"",'Split days'!$B$2:$B$401,'Split days'!$B$2:$B$401&""))
A11: Hyrox: stations ×2 | B11: 2 | C11: Stations A, Stations B | D11: Hyrox: two station sessions covering all eight stations. | E11: Yes | F11: =SUMPRODUCT(('Split days'!$A$2:$A$401=A11)/COUNTIFS('Split days'!$A$2:$A$401,'Split days'!$A$2:$A$401&"",'Split days'!$B$2:$B$401,'Split days'!$B$2:$B$401&""))
A12: Hyrox: strength + stations | B12: 3 | C12: Strength A, Stations, Strength B | D12: Hyrox: two strength days and one station day. | E12: Yes | F12: =SUMPRODUCT(('Split days'!$A$2:$A$401=A12)/COUNTIFS('Split days'!$A$2:$A$401,'Split days'!$A$2:$A$401&"",'Split days'!$B$2:$B$401,'Split days'!$B$2:$B$401&""))
A13: Push / Pull / Legs / Upper | B13: 4 | C13: Push, Pull, Legs, Upper | D13: 4 lifting days, muscle focus: push, pull and legs, plus an upper day for extra chest, back and arms. | E13: Yes | F13: =SUMPRODUCT(('Split days'!$A$2:$A$401=A13)/COUNTIFS('Split days'!$A$2:$A$401,'Split days'!$A$2:$A$401&"",'Split days'!$B$2:$B$401,'Split days'!$B$2:$B$401&""))

Sheet Split days
A1: Split | B1: Day name | C1: Order | D1: Exercise | E1: Role | F1: Sets | G1: Reps (low) | H1: Reps (high) | I1: Rest (s) | J1: Notes
A2: Full body ×1 | B2: Full body | C2: 1 | D2: Any squat | E2: Main
A3: Full body ×1 | B3: Full body | C3: 2 | D3: Any horizontal push (bench, press-up) | E3: Main
A4: Full body ×1 | B4: Full body | C4: 3 | D4: Any hinge accessory (RDL, bridge) | E4: Accessory
A5: Full body ×1 | B5: Full body | C5: 4 | D5: Any horizontal pull (row) | E5: Accessory
A6: Full body ×1 | B6: Full body | C6: 5 | D6: Any vertical push (overhead press) | E6: Accessory
A7: Full body ×1 | B7: Full body | C7: 6 | D7: Any core | E7: Accessory
A8: Full body ×2 | B8: Full body A | C8: 1 | D8: Any squat | E8: Main
A9: Full body ×2 | B9: Full body A | C9: 2 | D9: Any horizontal push (bench, press-up) | E9: Main
A10: Full body ×2 | B10: Full body A | C10: 3 | D10: Any horizontal pull (row) | E10: Accessory
A11: Full body ×2 | B11: Full body A | C11: 4 | D11: Any calf raise | E11: Accessory
A12: Full body ×2 | B12: Full body A | C12: 5 | D12: Any core | E12: Accessory
A13: Full body ×2 | B13: Full body B | C13: 1 | D13: Any hinge (deadlift) | E13: Main
... A140: PPL + Upper / Lower | B140: Lower | C140: 4 | D140: Any anti-rotation core | E140: Accessory
A141: Hyrox: stations ×2 | B141: Stations A | C141: 1 | D141: SkiErg (metres) | E141: Main | F141: 4 | G141: 250 | H141: 250 | I141: 60 | J141: Reps are metres.
A142: Hyrox: stations ×2 | B142: Stations A | C142: 2 | D142: Sled Push (metres) | E142: Main | F142: 4 | G142: 25 | H142: 25 | I142: 90 | J142: Reps are metres. Starts at your division's race weight.
A143: Hyrox: stations ×2 | B143: Stations A | C143: 3 | D143: Burpee Broad Jumps (metres) | E143: Accessory | F143: 3 | G143: 20 | H143: 20 | I143: 60 | J143: Reps are metres.
A144: Hyrox: stations ×2 | B144: Stations A | C144: 4 | D144: Wall Balls | E144: Accessory | F144: 4 | G144: 15 | H144: 20 | I144: 60
A145: Hyrox: stations ×2 | B145: Stations A | C145: 5 | D145: Any core | E145: Accessory
A146: Hyrox: stations ×2 | B146: Stations B | C146: 1 | D146: Rowing (metres) | E146: Main | F146: 4 | G146: 250 | H146: 250 | I146: 60 | J146: Reps are metres.
A147: Hyrox: stations ×2 | B147: Stations B | C147: 2 | D147: Sled Pull (metres) | E147: Main | F147: 4 | G147: 25 | H147: 25 | I147: 90 | J147: Reps are metres. Starts at your division's race weight.
A148: Hyrox: stations ×2 | B148: Stations B | C148: 3 | D148: Farmers Carry (metres) | E148: Accessory | F148: 4 | G148: 50 | H148: 50 | I148: 60 | J148: Reps are metres. Weight is per hand.
A149: Hyrox: stations ×2 | B149: Stations B | C149: 4 | D149: Sandbag Lunges (metres) | E149: Accessory | F149: 3 | G149: 25 | H149: 25 | I149: 60 | J149: Reps are metres.
A150: Hyrox: stations ×2 | B150: Stations B | C150: 5 | D150: Any anti-rotation core | E150: Accessory
A151: Hyrox: strength + stations | B151: Strength A | C151: 1 | D151: Any squat | E151: Main
A152: Hyrox: strength + stations | B152: Strength A | C152: 2 | D152: Any horizontal push (bench, press-up) | E152: Main
A153: Hyrox: strength + stations | B153: Strength A | C153: 3 | D153: Any horizontal pull (row) | E153: Accessory
A154: Hyrox: strength + stations | B154: Strength A | C154: 4 | D154: Any calf raise | E154: Accessory
A155: Hyrox: strength + stations | B155: Strength A | C155: 5 | D155: Any core | E155: Accessory
A156: Hyrox: strength + stations | B156: Stations | C156: 1 | D156: SkiErg (metres) | E156: Main | F156: 3 | G156: 250 | H156: 250 | I156: 45 | J156: Reps are metres.
A157: Hyrox: strength + stations | B157: Stations | C157: 2 | D157: Sled Push (metres) | E157: Main | F157: 3 | G157: 25 | H157: 25 | I157: 75 | J157: Reps are metres.
A158: Hyrox: strength + stations | B158: Stations | C158: 3 | D158: Sled Pull (metres) | E158: Accessory | F158: 3 | G158: 25 | H158: 25 | I158: 75 | J158: Reps are metres.
A159: Hyrox: strength + stations | B159: Stations | C159: 4 | D159: Burpee Broad Jumps (metres) | E159: Accessory | F159: 3 | G159: 20 | H159: 20 | I159: 45 | J159: Reps are metres.
A160: Hyrox: strength + stations | B160: Stations | C160: 5 | D160: Rowing (metres) | E160: Accessory | F160: 3 | G160: 250 | H160: 250 | I160: 45 | J160: Reps are metres.
A161: Hyrox: strength + stations | B161: Stations | C161: 6 | D161: Farmers Carry (metres) | E161: Accessory | F161: 3 | G161: 50 | H161: 50 | I161: 45 | J161: Reps are metres. Weight is per hand.
A162: Hyrox: strength + stations | B162: Stations | C162: 7 | D162: Sandbag Lunges (metres) | E162: Accessory | F162: 3 | G162: 25 | H162: 25 | I162: 45 | J162: Reps are metres.
A163: Hyrox: strength + stations | B163: Stations | C163: 8 | D163: Wall Balls | E163: Accessory | F163: 3 | G163: 20 | H163: 20 | I163: 45
A164: Hyrox: strength + stations | B164: Strength B | C164: 1 | D164: Any hinge (deadlift) | E164: Main
A165: Hyrox: strength + stations | B165: Strength B | C165: 2 | D165: Any vertical pull (pull-up, pulldown) | E165: Main
A166: Hyrox: strength + stations | B166: Strength B | C166: 3 | D166: Any lunge / split squat | E166: Accessory
...

Sheet Strength by goal
A1: Programme | B1: Role | C1: Sets | D1: Reps (low) | E1: Reps (high) | F1: Rest (s) | G1: Notes
A2: First 5K | B2: Main | C2: 3 | D2: 5 | E2: 8 | F2: 150
A3: First 5K | B3: Accessory | C3: 2 | D3: 8 | E3: 12 | F3: 90
A4: Faster 5K | B4: Main | C4: 3 | D4: 5 | E4: 8 | F4: 150
A5: Faster 5K | B5: Accessory | C5: 2 | D5: 8 | E5: 12 | F5: 60
A6: Faster 10K | B6: Main | C6: 3 | D6: 5 | E6: 8 | F6: 150
A7: Faster 10K | B7: Accessory | C7: 2 | D7: 8 | E7: 12 | F7: 90
A8: Half marathon | B8: Main | C8: 3 | D8: 5 | E8: 8 | F8: 150
A9: Half marathon | B9: Accessory | C9: 2 | D9: 8 | E9: 12 | F9: 90
A10: Marathon | B10: Main | C10: 3 | D10: 5 | E10: 8 | F10: 150
A11: Marathon | B11: Accessory | C11: 2 | D11: 8 | E11: 12 | F11: 90
A12: Build strength | B12: Main | C12: 5 | D12: 4 | E12: 6 | F12: 150
A13: Build strength | B13: Accessory | C13: 3 | D13: 8 | E13: 10 | F13: 90
... A19: Hyrox | B19: Accessory | C19: 3 | D19: 10 | E19: 15 | F19: 60
A21: Current app defaults. Running goals share the 'running' prescription today; set each one as you like.
A22: Weights progress automatically (double progression): add reps up to the top of the range, then add weight.

Sheet Rules
A1: Rule | B1: Beginner | C1: Intermediate | D1: Advanced | E1: Notes
A2: Starting volume if they don't run yet (km/week) | B2: 8 | C2: 15 | D2: 25 | E2: Used when the runner answers 0 or doesn't know.
A3: Minimum starting volume (km/week) | B3: 8 | C3: 15 | D3: 25 | E3: Their answer is raised to at least this.
A4: Maximum starting volume (km/week) | B4: 30 | C4: 60 | D4: 100 | E4: Their answer is capped at this.
A5: Longest single run (km) | B5: 10 | C5: 21 | D5: 32 | E5: No run is longer than this, except in race programmes (5K to marathon, Hyrox), which use their own long-run cap on the Programmes tab.
A6: Shortest run (km) | B6: 3 | C6: 3 | D6: 4 | E6: Runs shorter than this are dropped or merged.
A7: Max weekly increase (fraction) | B7: 0.1 | C7: 0.1 | D7: 0.12 | E7: 0.10 = 10%. Applies to what they actually ran, not just the plan.
A8: Long run share when 'auto' (fraction of week) | B8: 0.3 | C8: 0.3 | D8: 0.35 | E8: Used when Run weeks → Long run is 'auto'.
A9: Example runner (km/week) | B9: 15 | C9: 30 | D9: 50 | E9: Only for the grey example columns in Run weeks.
A10: Warm-up and cool-down, each (fraction of week) | B10: 0.06 | C10: 0.06 | D10: 0.06 | E10: Added to rep and tempo sessions. Kept between the min and max below.
A11: Warm-up minimum (km) | B11: 1.5 | C11: 1.5 | D11: 1.5 | E11: Also used when the long run and sessions already fill the week.
A12: Warm-up maximum (km) | B12: 2 | C12: 2.5 | D12: 3
A13: Fast reps max (fraction of week): I, R, 5K, hills | B13: 0.1 | C13: 0.1 | D13: 0.1 | E13: Hard running per session. Lower-volume runners get fewer reps; rep lengths never change.
A14: Fast reps floor (km) | B14: 3 | C14: 6 | D14: 8 | E14: Always allowed at least this much, whatever the week's volume.
A15: Threshold reps max (fraction of week): T, 10K | B15: 0.15 | C15: 0.15 | D15: 0.15
A16: Threshold reps floor (km) | B16: 3 | C16: 3 | D16: 3
A17: Steady reps max (fraction of week): STEADY, M, HM | B17: 0.25 | C17: 0.25 | D17: 0.25
A18: Steady reps floor (km) | B18: 4 | C18: 4 | D18: 4
A19: Recovery run max (fraction of long run) | B19: 0.6 | C19: 0.6 | D19: 0.6 | E19: Spare volume beyond these lengths adds an easy run if there's a free day.
A20: Easy run max (fraction of long run) | B20: 0.85 | C20: 0.85 | D20: 0.85
A21: Shakeout max (fraction of week) | B21: 0.15 | C21: 0.15 | D21: 0.15
A22: Recovery week after the programme (fraction of starting) | B22: 0.6 | C22: 0.6 | D22: 0.6 | E22: Easy running only, then the programme repeats from their recent running.
A23: Ease down per week when above race-ready (fraction) | B23: 0.15 | C23: 0.15 | D23: 0.15 | E23: Runners doing more than the race needs come down to its race-ready volume this much a week.
A24: Easy first week after a race (fraction of current) | B24: 0.6 | C24: 0.6 | D24: 0.6 | E24: Only if they say in onboarding they've raced in the last two weeks and want an easy week.
A26: Current app defaults are filled in; change any yellow value.

Sheet Lists
A1: Programmes | B1: Session types | C1: Phases | D1: Zones | E1: Splits | F1: Roles | G1: Yes / No | H1: Strength emphasis | I1: Exercises
A2: First 5K | B2: Easy | C2: Base | D2: E | E2: Full body ×1 | F2: Main | G2: Yes | H2: Normal | I2: Any squat
A3: Faster 5K | B3: Recovery | C3: Build | D3: STEADY | E3: Full body ×2 | F3: Accessory | G3: No | H3: Heavy | I3: Any hinge (deadlift)
A4: Faster 10K | B4: Long | C4: Peak | D4: M | E4: Full body ×3 | H4: Light | I4: Any hinge accessory (RDL, bridge)
A5: Half marathon | B5: Tempo | C5: Deload | D5: HM | E5: Upper / Lower | H5: None | I5: Any lunge / split squat
A6: Marathon | B6: Intervals | C6: Taper | D6: T | E6: Push / Pull / Legs | I6: Any calf raise
A7: Build strength | B7: Progression | C7: Race week | D7: 10K | E7: Push / Pull / Legs ×2 | I7: Any horizontal push (bench, press-up)
A8: Build muscle | B8: Fartlek | D8: 5K | E8: Upper / Lower / Full | I8: Any vertical push (overhead press)
A9: Balanced hybrid | B9: Hills | D9: I | E9: PPL + Upper / Lower | I9: Any horizontal pull (row)
A10: Hyrox | B10: Shakeout | D10: R | E10: PPL + Upper + Shoulders & arms | I10: Any vertical pull (pull-up, pulldown)
B11: Compromised | E11: Hyrox: stations ×2 | I11: Any arms
B12: Race | E12: Hyrox: strength + stations | I12: Any core
E13: Push / Pull / Legs / Upper | I13: Any anti-rotation core
I14: Any Hyrox station
I15: Arnold Press
I16: Barbell Back Squat
I17: Barbell Bench Press
I18: Barbell Curl
I19: Barbell Deadlift
I20: Barbell Hip Thrust
I21: Barbell Row
I22: Bulgarian Split Squat
I23: Burpee
I24: Burpee Broad Jumps (metres)
I25: Cable Crunch
... I94: Wall Balls
